Traceback (most recent call last):
  File "/home/jfhlewyee/anaconda3/envs/jb/lib/python3.13/site-packages/jupyter_cache/executors/utils.py", line 58, in single_nb_execution
    executenb(
    ~~~~~~~~~^
        nb,
        ^^^
    ...<4 lines>...
        **kwargs,
        ^^^^^^^^^
    )
    ^
  File "/home/jfhlewyee/anaconda3/envs/jb/lib/python3.13/site-packages/nbclient/client.py", line 1319, in execute
    return NotebookClient(nb=nb, resources=resources, km=km, **kwargs).execute()
           ~~~~~~~~~~~~~~~~~~~~~~~~~~~~~~~~~~~~~~~~~~~~~~~~~~~~~~~~~~~~~~~~~~~^^
  File "/home/jfhlewyee/anaconda3/envs/jb/lib/python3.13/site-packages/jupyter_core/utils/__init__.py", line 165, in wrapped
    return loop.run_until_complete(inner)
           ~~~~~~~~~~~~~~~~~~~~~~~^^^^^^^
  File "/home/jfhlewyee/anaconda3/envs/jb/lib/python3.13/asyncio/base_events.py", line 720, in run_until_complete
    return future.result()
           ~~~~~~~~~~~~~^^
  File "/home/jfhlewyee/anaconda3/envs/jb/lib/python3.13/site-packages/nbclient/client.py", line 709, in async_execute
    await self.async_execute_cell(
        cell, index, execution_count=self.code_cells_executed + 1
    )
  File "/home/jfhlewyee/anaconda3/envs/jb/lib/python3.13/site-packages/nbclient/client.py", line 1062, in async_execute_cell
    await self._check_raise_for_error(cell, cell_index, exec_reply)
  File "/home/jfhlewyee/anaconda3/envs/jb/lib/python3.13/site-packages/nbclient/client.py", line 918, in _check_raise_for_error
    raise CellExecutionError.from_cell_and_msg(cell, exec_reply_content)
nbclient.exceptions.CellExecutionError: An error occurred while executing the following cell:
------------------
p = figure()
p.circle(data["sepal_width"], data["sepal_length"], fill_color=data["species"], size=data["sepal_length"])
show(p)
------------------


[0;31m---------------------------------------------------------------------------[0m
[0;31mNameError[0m                                 Traceback (most recent call last)
Cell [0;32mIn[2], line 2[0m
[1;32m      1[0m p [38;5;241m=[39m figure()
[0;32m----> 2[0m p[38;5;241m.[39mcircle([43mdata[49m[[38;5;124m"[39m[38;5;124msepal_width[39m[38;5;124m"[39m], data[[38;5;124m"[39m[38;5;124msepal_length[39m[38;5;124m"[39m], fill_color[38;5;241m=[39mdata[[38;5;124m"[39m[38;5;124mspecies[39m[38;5;124m"[39m], size[38;5;241m=[39mdata[[38;5;124m"[39m[38;5;124msepal_length[39m[38;5;124m"[39m])
[1;32m      3[0m show(p)

[0;31mNameError[0m: name 'data' is not defined

